Workbook

Sheet BBDD
A1: RUT | B1: Número de Documento | C1: Nombre Empresa | D1: Código de Ficha | E1: Email | F1: Email Personal | G1: Nombre Completo | H1: Cargo | I1: Nombre Supervisor | J1: Nombre Área | K1: Tipo de Contrato | L1: Fecha Ingreso Compañía | M1: Nomina de Pago | N1: Nombre Gerencia | O1: Lugar de Trabajo | P1: Tipo contratación
A2: 17382227 | B2: 17.382.227-8 | C2: Orizon S.A | D2: F1 | E2: humberto.galaz@gmail.com | F2: humberto.galaz@gmail.com | G2: Galaz Segovia Humberto Elias | H2: Supervisor(A) De Turno Pt | I2: Stephanie Nicole Navarro Marmiez | J2: Gerencia Logistica | K2: Plazo fijo | L2: 45964 | M2: Coronel Rol Tierra | N2: Gerencia Corp. Supply Chain | O2: Coronel | P2: Temporada (Con ocasión Temporada de Pesca)
A3: 18501236 | B3: 18.501.236-0 | C3: Orizon S.A | D3: F1 | E3: urquiola.loredana@gmail.com | F3: urquiola.loredana@gmail.com | G3: Espinoza Saez Katherine Loredana | H3: Ingeniero Programador Planificación Mantención | I3: Sebastian Ignacio Olate Vega | J3: Departamento Ingeniería | K3: Plazo fijo | L3: 45962 | M3: Coronel Rol Tierra | N3: Gerencia Corp. Negocio Seafood | O3: Coronel | P3: Rol General (Cargo permanente o proyección indefinido)
A4: 17861981 | B4: 17.861.981-0 | C4: Orizon S.A | D4: F3 | E4: carla.roca@orizon.cl | F4: carla.roca@orizon.cl | G4: Roca Galindo Carla Eugenia | H4: Supervisor(A) De Turno Pt | I4: Osvaldo Mardones Beltran | J4: Gerencia Logistica | K4: Plazo fijo | L4: 45962 | M4: Coronel Rol Tierra | N4: Gerencia Corp. Supply Chain | O4: Coronel | P4: Temporada (Con ocasión Temporada de Pesca)
A5: 20438291 | B5: 20.438.291-3 | C5: Orizon S.A | D5: F3 | E5: valediaze05@hotmail.com | F5: valediaze05@hotmail.com | G5: Diaz Elgueta Valentina Isabel | H5: Monitor(A) Calidad Ch | I5: Larisa Andrea Burgos Zavala | J5: Gerencia Gestión Integrada y Calidad | K5: Plazo fijo | L5: 45966 | M5: Coronel Rol Eventual | N5: Gerencia Corp. Negocio Seafood | O5: Coronel | P5: Temporada (Con ocasión Temporada de Pesca)
A6: 18821915 | B6: 18.821.915-2 | C6: Orizon S.A | D6: F3 | E6: monsalvezerik@gmail.com | F6: monsalvezerik@gmail.com | G6: Monsalvez Nuñez Erik Antonio | H6: Monitor(A) De Calidad | I6: Larisa Andrea Burgos Zavala | J6: Gerencia Gestión Integrada y Calidad | K6: Plazo fijo | L6: 45966 | M6: Coronel Rol Eventual | N6: Gerencia Corp. Negocio Seafood | O6: Coronel | P6: Temporada (Con ocasión Temporada de Pesca)
A7: 19139667 | B7: 19.139.667-7 | C7: Orizon S.A | D7: F3 | E7: ANTO.LOZANO95@GMAIL.COM | F7: ANTO.LOZANO95@GMAIL.COM | G7: Lozano Aniñir Antonia | H7: Monitor(A) De Calidad | I7: Larisa Andrea Burgos Zavala | J7: Gerencia Gestión Integrada y Calidad | K7: Plazo fijo | L7: 45966 | M7: Coronel Rol Eventual | N7: Gerencia Corp. Negocio Seafood | O7: Coronel | P7: Temporada (Con ocasión Temporada de Pesca)
A8: 20362461 | B8: 20.362.461-1 | C8: Orizon S.A | D8: F5 | E8: yocelynmarianeladelcarmen18@gmail.com | F8: yocelynmarianeladelcarmen18@gmail.com | G8: Diaz Hidalgo Jocelyn Marianela Del Carmen | H8: Operador Elaboracion Php | I8: Marcos Antonio Nuñez Garcia | J8: Gerencia Producción Pesca | K8: Plazo fijo | L8: 45962 | M8: Coronel Rol Tierra | N8: Gerencia Corp. Negocio Seafood | O8: Coronel | P8: Temporada (Con ocasión Temporada de Pesca)
A9: 18816284 | B9: 18.816.284-3 | C9: Orizon S.A | D9: F3 | E9: RM.NUTDIET@GMAIL.COM | F9: RM.NUTDIET@GMAIL.COM | G9: Montaner Pereira Romina Fernanda | H9: Monitor(A) De Calidad | I9: Larisa Andrea Burgos Zavala | J9: Gerencia Gestión Integrada y Calidad | K9: Plazo fijo | L9: 45967 | M9: Coronel Rol Eventual | N9: Gerencia Corp. Negocio Seafood | O9: Coronel | P9: Temporada (Con ocasión Temporada de Pesca)
A10: 20362434 | B10: 20.362.434-4 | C10: Orizon S.A | D10: F1 | E10: Nksbastian@gmail.com | F10: Nksbastian@gmail.com | G10: Pastrana Ceballos Bastian Alonso | H10: Asistente Operaciones Pt | I10: Stephanie Nicole Navarro Marmiez | J10: Gerencia Logistica | K10: Plazo fijo | L10: 45964 | M10: Coronel Rol Tierra | N10: Gerencia Corp. Supply Chain | O10: Coronel | P10: Temporada (Con ocasión Temporada de Pesca)
A11: 15529956 | B11: 15.529.956-8 | C11: Orizon S.A | D11: F5 | E11: MARYCARRASCO117@GMAIL.COM | F11: MARYCARRASCO117@GMAIL.COM | G11: Carrasco Copelli Mariana Elizabeth | H11: Monitor(A) De Calidad | I11: Larisa Andrea Burgos Zavala | J11: Gerencia Gestión Integrada y Calidad | K11: Plazo fijo | L11: 45968 | M11: Coronel Rol Eventual | N11: Gerencia Corp. Negocio Seafood | O11: Coronel | P11: Temporada (Con ocasión Temporada de Pesca)
A12: 20196888 | B12: 20.196.888-7 | C12: Orizon S.A | D12: F1 | E12: javiierahidalgo@gmail.com | F12: javiierahidalgo@gmail.com | G12: Hidalgo Reyes Javiera Scarlet | H12: Asistente Operaciones Pt | I12: Osvaldo Mardones Beltran | J12: Gerencia Logistica | K12: Plazo fijo | L12: 45964 | M12: Coronel Rol Tierra | N12: Gerencia Corp. Supply Chain | O12: Escuadrón | P12: Temporada (Con ocasión Temporada de Pesca)
A13: 14213629 | B13: 14.213.629-5 | C13: Orizon S.A | D13: F1 | E13: juanhpi@gmail.com | F13: juanhpi@gmail.com | G13: Palma Ibarra Juan Hernaldo | H13: Mecanico Frigorista | I13: Carlos Javier Orellana Gonzalez | J13: Departamento Ingeniería | K13: Plazo fijo | L13: 45962 | M13: Coronel Rol Tierra | N13: Gerencia Corp. Negocio Seafood | O13: Escuadrón | P13: Rol General (Cargo permanente o proyección indefinido)
... A123: 9713420 | B123: 9.713.420-0 | C123: Orizon S.A | D123: F1 | E123: guillermo.ramirez@orizon.cl | F123: gramirezr1965@gmail.com | G123: Ramirez Rodriguez Guillermo Elias | H123: Asistente Produccion | I123: Roberto Carlos Carcamo Ojeda | J123: Gerencia Producción Pesca | K123: Indefinido | L123: 41640 | M123: Coronel Rol Tierra | N123: Gerencia Corp. Negocio Seafood | O123: Coronel | P123: Rol General (Cargo permanente o proyección indefinido)
A124: 16038547 | B124: 16.038.547-2 | C124: Orizon S.A | D124: F1 | G124: Herrera Araya Cristian Alexis | H124: Aspirante Tripulante | I124: Eduardo Esteban Gonzalez Martinez | J124: Gerencia de Flota y Abastecimiento de Materias Primas | K124: Obra | L124: 45681 | M124: Coronel Rol Flota | N124: Gerencia Corp. Negocio Seafood | O124: Coronel | P124: Temporada (Con ocasión Temporada de Pesca)
A125: 18417675 | B125: 18.417.675-0 | C125: Orizon S.A | D125: F1 | E125: ed.neira.h@gmail.com | F125: ed.neira.h@gmail.com | G125: Neira Henriquez Edinson Benicio | H125: Aspirante Tripulante | I125: Eduardo Esteban Gonzalez Martinez | J125: Gerencia de Flota y Abastecimiento de Materias Primas | K125: Obra | L125: 45826 | M125: Coronel Rol Flota | N125: Gerencia Corp. Negocio Seafood | O125: Coronel | P125: Temporada (Con ocasión Temporada de Pesca)
A126: 15614411 | B126: 15.614.411-8 | C126: Orizon S.A | D126: F1 | E126: carlos.ruiz@orizon.cl | F126: carlosruizlagos@gmail.com | G126: Ruiz Lagos Carlos Felipe | H126: Auditor(A) De Servicios | I126: Sebastian Antonio Ochoa Pizarro | J126: Depto Control Interno y Riesgos | K126: Indefinido | L126: 43836 | M126: Coronel Rol Tierra | N126: Gerencia General | O126: Coronel | P126: Rol General (Cargo permanente o proyección indefinido)
A127: 11722500 | B127: 11.722.500-3 | C127: Orizon S.A | D127: F1 | E127: jorge.oyarzun@orizon.cl | F127: joya1807@hotmail.com | G127: Oyarzun Araya Jorge Andres | H127: Auditor(A) De Servicios | I127: Sebastian Antonio Ochoa Pizarro | J127: Depto Control Interno y Riesgos | K127: Indefinido | L127: 44593 | M127: Coquimbo | N127: Gerencia General | O127: Coquimbo | P127: Rol General (Cargo permanente o proyección indefinido)
A128: 13685377 | B128: 13.685.377-5 | C128: Orizon S.A | D128: F1 | E128: javier.dominguez@nutrisco.com | F128: javierdominguez.garrido@gmail.com | G128: Dominguez Garrido Javier | H128: Auditor(A) Interno | I128: Sebastian Antonio Ochoa Pizarro | J128: Depto Control Interno y Riesgos | K128: Indefinido | L128: 41778 | M128: Santiago | N128: Gerencia General | O128: Santiago | P128: Rol General (Cargo permanente o proyección indefinido)
A129: 15529692 | B129: 15.529.692-5 | C129: Orizon S.A | D129: F1 | E129: cristian.lefimil@orizon.cl | F129: calglefi@gmail.com | G129: Lefimil Gonzalez Cristian Armando | H129: Auditor(A) Junior | I129: Carlos Felipe Ruiz Lagos | J129: Depto Control Interno y Riesgos | K129: Indefinido | L129: 43857 | M129: Coronel Rol Tierra | N129: Gerencia General | O129: Coronel | P129: Rol General (Cargo permanente o proyección indefinido)
A130: 12039485 | B130: 12.039.485-1 | C130: Orizon S.A | D130: F1 | E130: alex.diaz@orizon.cl | F130: DINGO669@HOTMAIL.COM | G130: Diaz Rubilar Alex Esteban | H130: Auxiliar Administrativo | I130: Rodrigo Alejandro Jofré Valdebenito | J130: Gerencia SST y Servicio a las Personas | K130: Indefinido | L130: 45558 | M130: Coronel Rol Tierra | N130: Gerencia Corp. Personas y SST | O130: Coronel | P130: Rol General (Cargo permanente o proyección indefinido)
A131: 17444650 | B131: 17.444.650-4 | C131: Orizon S.A | D131: F5 | E131: pili1744465042211@gmail.com | F131: pili1744465042211@gmail.com | G131: Guerrero Vega Ingrid Del Pilar | H131: Auxiliar Aseo | I131: Luis Jose Vasquez Sandoval | J131: Gerencia Producción Pesca | K131: Plazo fijo | L131: 45938 | M131: Coronel Rol Tierra | N131: Gerencia Corp. Negocio Seafood | O131: Coronel | P131: Temporada (Con ocasión Temporada de Pesca)
A132: 17232589 | B132: 17.232.589-0 | C132: Orizon S.A | D132: F5 | E132: andreaguajardo1111@gmail.com | F132: andreaguajardo1111@gmail.com | G132: Meneses Guajardo Margarita Andrea | H132: Auxiliar Aseo | I132: Marcos Antonio Nuñez Garcia | J132: Gerencia Producción Pesca | K132: Plazo fijo | L132: 45938 | M132: Coronel Rol Tierra | N132: Gerencia Corp. Negocio Seafood | O132: Coronel | P132: Temporada (Con ocasión Temporada de Pesca)
A133: 8978847 | B133: 8.978.847-1 | C133: Orizon S.A | D133: F1 | E133: pedroconchagutierrez19@gmail.com | F133: pedroconchagutierrez19@gmail.com | G133: Concha Gutierrez Pedro Pablo | H133: Ayudante Bodega Pt | I133: Luis Javier Piñones Segovia | J133: Gerencia Sales Harinas y Aceite | K133: Indefinido | L133: 40513 | M133: Coquimbo | N133: Gerencia Corp. Supply Chain | O133: Coquimbo | P133: Rol General (Cargo permanente o proyección indefinido)
A134: 14131725 | B134: 14.131.725-3 | C134: Orizon S.A | D134: F1 | E134: ivanf6587@gmail.com | F134: ivanf6587@gmail.com | G134: Flores Galleguillos Ivan Andres | H134: Ayudante Bodega Pt | I134: Luis Javier Piñones Segovia | J134: Gerencia Sales Harinas y Aceite | K134: Indefinido | L134: 44929 | M134: Coquimbo | N134: Gerencia Corp. Supply Chain | O134: Coquimbo | P134: Rol General (Cargo permanente o proyección indefinido)
A135: 14385954 | B135: 14.385.954-1 | C135: Orizon S.A | D135: F4 | E135: ulises730@gmail.com | F135: ulises730@gmail.com | G135: Galvez Alfaro Ulises Andres | H135: Ayudante Bodega Pt | I135: Luis Javier Piñones Segovia | J135: Gerencia Sales Harinas y Aceite | K135: Plazo fijo | L135: 45761 | M135: Coquimbo | N135: Gerencia Corp. Supply Chain | O135: Coquimbo | P135: Rol General (Cargo permanente o proyección indefinido)
A136: 17624797 | B136: 17.624.797-5 | C136: Orizon S.A | D136: F1 | E136: danieltapia.m90@gmail.com | F136: danieltapia.m90@gmail.com | G136: Tapia Miranda Daniel Jordan Constantino | H136: Ayudante Bodega Pt | I136: Luis Javier Piñones Segovia | J136: Gerencia Sales Harinas y Aceite | K136: Indefinido | L136: 45334 | M136: Coquimbo | N136: Gerencia Corp. Supply Chain | O136: Coquimbo | P136: Rol General (Cargo permanente o proyección indefinido)
... A306: 21295688 | B306: 21.295.688-0 | C306: Nutrisco S.A. | D306: F1 | E306: fiorella.montoya@nutrisco.com | F306: fiorella.montoya.p@gmail.com | G306: Montoya Portella Fiorella | H306: Gerente Corporativa De Sostenibilidad | I306: Rigoberto Rojo Rojas | J306: Gerencia Corp. Sostenibilidad | K306: Indefinido | L306: 45474 | M306: Rol Privado | N306: Gerencia Corp. Sostenibilidad | O306: Santiago | P306: Rol General (Cargo permanente o proyección indefinido)
A307: 10844186 | B307: 10.844.186-0 | C307: Nutrisco S.A. | D307: F1 | E307: cristian.larrain@nutrisco.com | G307: Larrain Reyes Cristian | H307: Gerente Corporativo Comercial Y Marketing | I307: Rigoberto Rojo Rojas | J307: Gerencia Corp Comercial y Marketing | K307: Indefinido | L307: 42681 | M307: Rol Privado | N307: Gerencia Corp. Comercial y Marketing | O307: Santiago | P307: Rol General (Cargo permanente o proyección indefinido)
A308: 10093016 | B308: 10.093.016-1 | C308: Nutrisco S.A. | D308: F1 | E308: juancarlos.macaya@nutrisco.com | F308: jc.macayag@gmail.com | G308: Macaya Gastigar Juan Carlos | H308: Gerente Corporativo De Administracion | I308: Rigoberto Rojo Rojas | J308: Gerencia Corp. Administracion | K308: Indefinido | L308: 40513 | M308: Rol Privado | N308: Gerencia Corp. de Administracion | O308: Santiago | P308: Rol General (Cargo permanente o proyección indefinido)
A309: 13271928 | B309: 13.271.928-4 | C309: Nutrisco S.A. | D309: F1 | E309: michel.bouiey@nutrisco.com | F309: mbouiey@uc.cl | G309: Bouiey Sierra Michel | H309: Gerente Corporativo De Finanzas Y Tecnologia | I309: Rigoberto Rojo Rojas | J309: Gerencia Corp. Finanzas y Tecnología | K309: Indefinido | L309: 45047 | M309: Rol Privado | N309: Gerencia Corp. Finanzas y Tecnologia | O309: Santiago | P309: Rol General (Cargo permanente o proyección indefinido)
A310: 11833668 | B310: 11.833.668-2 | C310: Nutrisco S.A. | D310: F1 | E310: francisca.prieto@nutrisco.com | F310: franciscaprietoarroyo@gmail.com | G310: Prieto Arroyo María Francisca | H310: Gerente Corporativo De Personas Y Sst | I310: Rigoberto Rojo Rojas | J310: Gerencia Corp. Personas | K310: Indefinido | L310: 45523 | M310: Rol Privado | N310: Gerencia Corp. Personas y SST | O310: Santiago | P310: Rol General (Cargo permanente o proyección indefinido)
A311: 13134939 | B311: 13.134.939-4 | C311: Nutrisco S.A. | D311: F1 | E311: gerardo.barrera@nutrisco.com | F311: gbarreras77@gmail.com | G311: Barrera Sanzana Gerardo | H311: Gerente Corporativo De Supply Chain | I311: Rigoberto Rojo Rojas | J311: Gerencia Supply Chain | K311: Indefinido | L311: 42917 | M311: Rol Privado | N311: Gerencia Corp. Supply Chain | O311: Santiago | P311: Rol General (Cargo permanente o proyección indefinido)
A312: 13724355 | B312: 13.724.355-5 | C312: Nutrisco S.A. | D312: F1 | E312: ignacio.garrido@nutrisco.com | F312: igarrido_ing@hotmail.com | G312: Garrido Concha Ignacio Andrés | H312: Gerente De Abastecimiento | I312: Gerardo Barrera Sanzana | J312: Gerencia de Abastecimiento | K312: Indefinido | L312: 45505 | M312: Rol Privado | N312: Gerencia Corp. Negocio Seafood | O312: Coronel | P312: Rol General (Cargo permanente o proyección indefinido)
A313: 11978482 | B313: 11.978.482-4 | C313: Nutrisco S.A. | D313: F1 | E313: claudia.zamorano@nutrisco.com | F313: claudiazamoranor@hotmail.com | G313: Zamorano Raventos Claudia | H313: Gerente De Administracion De Activos Y Seguros | I313: Juan Carlos Macaya Gastigar | J313: Gerencia de Administración, Activos y Seguros Planta | K313: Indefinido | L313: 41609 | M313: Rol Privado | N313: Gerencia Corp. de Administracion | O313: Santiago | P313: Rol General (Cargo permanente o proyección indefinido)
A314: 12010509 | B314: 12.010.509-4 | C314: Nutrisco S.A. | D314: F1 | E314: bayardo.vado@nutrisco.com | F314: bayardovado@gmail.com | G314: Vado Uribe Bayardo | H314: Gerente De Contabilidad | I314: Juan Carlos Macaya Gastigar | J314: Gerencia Contabilidad | K314: Indefinido | L314: 43276 | M314: Rol Privado | N314: Gerencia Corp. de Administracion | O314: Santiago | P314: Rol General (Cargo permanente o proyección indefinido)
A315: 13425908 | B315: 13.425.908-6 | C315: Orizon S.A | D315: F1 | E315: jorge.buzeta@orizon.cl | F315: jbuzetan@gmail.com | G315: Buzeta Negroni Jorge Andres | H315: Gerente De Flota Y Abastecimiento De Mmpp Pesca | I315: Fernando Ayala Burgemeister | J315: Gerencia de Flota y Abastecimiento de Materias Primas | K315: Indefinido | L315: 41330 | M315: Rol Privado | N315: Gerencia Corp. Negocio Seafood | O315: Coronel | P315: Rol General (Cargo permanente o proyección indefinido)
A316: 16155554 | B316: 16.155.554-1 | C316: Nutrisco S.A. | D316: F1 | E316: constanza.aravena@nutrisco.com | F316: constanza.aravena3@gmail.com | G316: Aravena Sandoval María Constanza | H316: Gerente De Logistica | I316: Gerardo Barrera Sanzana | J316: Gerencia Supply Chain | K316: Indefinido | L316: 45523 | M316: Rol Privado | N316: Gerencia Corp. Supply Chain | O316: 4 Esquinas | P316: Rol General (Cargo permanente o proyección indefinido)
A317: 24741043 | B317: 24.741.043-0 | C317: Nutrisco S.A. | D317: F1 | E317: mariaflorencia.barua@nutrisco.com | F317: florbarua@gmail.com | G317: Barua . M.Florencia | H317: Gerente De Marketing | I317: Cristian Larrain Reyes | J317: Gerencia de Marketing | K317: Indefinido | L317: 44522 | M317: Rol Privado | N317: Gerencia Corp. Comercial y Marketing | O317: Santiago | P317: Rol General (Cargo permanente o proyección indefinido)
A318: 10034310 | B318: 10.034.310-k | C318: Nutrisco S.A. | D318: F1 | E318: ignacio.astete@nutrisco.com | G318: Astete Heimpell Ignacio Arturo | H318: Gerente De Negocio North America | I318: Rigoberto Rojo Rojas | J318: Nutrisco North America LLC | K318: Indefinido | L318: 45341 | M318: Rol Privado | N318: Gerencia Nutrisco North America LLC | O318: Santiago | P318: Rol General (Cargo permanente o proyección indefinido)
...

Sheet Atención 2025
A1: Número | B1: RUT | C1: Nombre | D1: Cargo | E1: Área | F1: Contrato | G1: Nómina | H1: Gerencia Corporativa | I1: Lugar | J1: Tipo Contratación | K1: Ingreso | L1: Razón | M1: Ficha | N1: E-mail | O1: Fecha | P1: Canal | Q1: Consulta | R1: Observación | S1: Respuesta | T1: Estado
A2: 19577640 | B2: =VLOOKUP(A2,BBDD!$1:$1048653,2,0) -> 19.577.640-7 | C2: =VLOOKUP(A2,BBDD!$1:$1048653,7,0) -> Faundez Roa Jorge Nicolás | D2: =VLOOKUP(A2,BBDD!$1:$1048653,8,0) -> Tripulante | E2: =VLOOKUP(A2,BBDD!$1:$1048653,10,0) -> Gerencia de Flota y Abastecimiento de Materias Primas | F2: =VLOOKUP(A2,BBDD!$1:$1048653,11,0) -> Indefinido | G2: =VLOOKUP(A2,BBDD!$1:$1048653,13,0) -> Coronel Rol flota | H2: =VLOOKUP(A2,BBDD!$1:$1048653,14,0) -> Gerencia Corp. Negocio Seafood | I2: =VLOOKUP(A2,BBDD!$1:$1048653,16,0) -> Rol General (Cargo permanente o proyección indefinido) | J2: =VLOOKUP(A2,BBDD!$1:$1048653,17,0) | K2: =VLOOKUP(A2,BBDD!$1:$1048653,12,0) -> 45611 | L2: =VLOOKUP(A2,BBDD!$1:$1048653,3,0) -> Orizon S.A | M2: =VLOOKUP(A2,BBDD!$1:$1048653,4,0) -> F2 | N2: =VLOOKUP(A2,BBDD!$1:$1048653,5,0) -> nicolasfaundezr@hotmail.com | O2: 45953 | P2: Oficina | Q2: Beneficios | R2: Inscripción Navidad | T2: Cerrado
A3: 19800216 | B3: =VLOOKUP(A3,BBDD!$1:$1048653,2,0) -> 19.800.216-k | C3: =VLOOKUP(A3,BBDD!$1:$1048653,7,0) -> Saez Torres Estefania Alejandra | D3: =VLOOKUP(A3,BBDD!$1:$1048653,8,0) -> Operario Apoyo Elaboracion | E3: =VLOOKUP(A3,BBDD!$1:$1048653,10,0) -> Gerencia Producción Pesca | F3: =VLOOKUP(A3,BBDD!$1:$1048653,11,0) -> Plazo fijo | G3: =VLOOKUP(A3,BBDD!$1:$1048653,13,0) -> Coronel Rol Eventual | H3: =VLOOKUP(A3,BBDD!$1:$1048653,14,0) -> Gerencia Corp. Negocio Seafood | I3: =VLOOKUP(A3,BBDD!$1:$1048653,16,0) -> Temporada (Con ocasión Temporada de Pesca) | J3: =VLOOKUP(A3,BBDD!$1:$1048653,17,0) | K3: =VLOOKUP(A3,BBDD!$1:$1048653,12,0) -> 45941 | L3: =VLOOKUP(A3,BBDD!$1:$1048653,3,0) -> Orizon S.A | M3: =VLOOKUP(A3,BBDD!$1:$1048653,4,0) -> F1 | N3: =VLOOKUP(A3,BBDD!$1:$1048653,5,0) -> saeztorres16@gmail.com | O3: 45953 | P3: Oficina | Q3: Asistencia | R3: Accidente leve | S3: Derivado a SST | T3: Cerrado
A4: 17320823 | B4: =VLOOKUP(A4,BBDD!$1:$1048653,2,0) -> 17.320.823-5 | C4: =VLOOKUP(A4,BBDD!$1:$1048653,7,0) -> Fonseca Cardenas Melisa Isabel | D4: =VLOOKUP(A4,BBDD!$1:$1048653,8,0) -> Administrativo(A) Prod Sap Y Sernapesca | E4: =VLOOKUP(A4,BBDD!$1:$1048653,10,0) -> Gerencia Producción Pesca | F4: =VLOOKUP(A4,BBDD!$1:$1048653,11,0) -> Indefinido | G4: =VLOOKUP(A4,BBDD!$1:$1048653,13,0) -> Coronel Rol Tierra | H4: =VLOOKUP(A4,BBDD!$1:$1048653,14,0) -> Gerencia Corp. Negocio Seafood | I4: =VLOOKUP(A4,BBDD!$1:$1048653,16,0) -> Rol General (Cargo permanente o proyección indefinido) | J4: =VLOOKUP(A4,BBDD!$1:$1048653,17,0) | K4: =VLOOKUP(A4,BBDD!$1:$1048653,12,0) -> 42738 | L4: =VLOOKUP(A4,BBDD!$1:$1048653,3,0) -> Orizon S.A | M4: =VLOOKUP(A4,BBDD!$1:$1048653,4,0) -> F1 | N4: =VLOOKUP(A4,BBDD!$1:$1048653,5,0) -> melissa.fonseca@orizon.cl | O4: 45953 | P4: Oficina | Q4: Vestimenta y EPP | R4: Reserva por LM | T4: Cerrado
A5: 16138010 | B5: =VLOOKUP(A5,BBDD!$1:$1048653,2,0) -> 16.138.010-5 | C5: =VLOOKUP(A5,BBDD!$1:$1048653,7,0) -> Saldias Soto Robinson Antonio | D5: =VLOOKUP(A5,BBDD!$1:$1048653,8,0) -> Despachador(A) Logistico | E5: =VLOOKUP(A5,BBDD!$1:$1048653,10,0) -> Gerencia Sales Harinas y Aceite | F5: =VLOOKUP(A5,BBDD!$1:$1048653,11,0) -> Indefinido | G5: =VLOOKUP(A5,BBDD!$1:$1048653,13,0) -> Coronel Rol Tierra | H5: =VLOOKUP(A5,BBDD!$1:$1048653,14,0) -> Gerencia Corp. Supply Chain | I5: =VLOOKUP(A5,BBDD!$1:$1048653,16,0) -> Rol General (Cargo permanente o proyección indefinido) | J5: =VLOOKUP(A5,BBDD!$1:$1048653,17,0) | K5: =VLOOKUP(A5,BBDD!$1:$1048653,12,0) -> 44896 | L5: =VLOOKUP(A5,BBDD!$1:$1048653,3,0) -> Orizon S.A | M5: =VLOOKUP(A5,BBDD!$1:$1048653,4,0) -> F1 | N5: =VLOOKUP(A5,BBDD!$1:$1048653,5,0) -> robinson.saldias@orizon.cl | O5: 45953 | P5: E-mail | Q5: Asignación Familiar | S5: Correo enviado | T5: Cerrado
A6: 13853030 | B6: =VLOOKUP(A6,BBDD!$1:$1048653,2,0) -> 13.853.030-2 | C6: =VLOOKUP(A6,BBDD!$1:$1048653,7,0) -> Burgos Zavala Larisa Andrea | D6: =VLOOKUP(A6,BBDD!$1:$1048653,8,0) -> Jefe(A) De Inocuidad E Higiene Consumo Humano | E6: =VLOOKUP(A6,BBDD!$1:$1048653,10,0) -> Gerencia Gestión Integrada y Calidad | F6: =VLOOKUP(A6,BBDD!$1:$1048653,11,0) -> Indefinido | G6: =VLOOKUP(A6,BBDD!$1:$1048653,13,0) -> Coronel Rol Tierra | H6: =VLOOKUP(A6,BBDD!$1:$1048653,14,0) -> Gerencia Corp. Negocio Seafood | I6: =VLOOKUP(A6,BBDD!$1:$1048653,16,0) -> Rol General (Cargo permanente o proyección indefinido) | J6: =VLOOKUP(A6,BBDD!$1:$1048653,17,0) | K6: =VLOOKUP(A6,BBDD!$1:$1048653,12,0) -> 40513 | L6: =VLOOKUP(A6,BBDD!$1:$1048653,3,0) -> Orizon S.A | M6: =VLOOKUP(A6,BBDD!$1:$1048653,4,0) -> F1 | N6: =VLOOKUP(A6,BBDD!$1:$1048653,5,0) -> larisa.burgos@orizon.cl | O6: 45953 | P6: Oficina | Q6: Vestimenta y EPP | R6: Cambio Talla | T6: Cerrado
A7: 18384012 | B7: =VLOOKUP(A7,BBDD!$1:$1048653,2,0) -> 18.384.012-6 | C7: =VLOOKUP(A7,BBDD!$1:$1048653,7,0) -> Contreras Alegria Andrea Nicole | D7: =VLOOKUP(A7,BBDD!$1:$1048653,8,0) -> Analista De Producto Final | E7: =VLOOKUP(A7,BBDD!$1:$1048653,10,0) -> Gerencia Gestión Integrada y Calidad | F7: =VLOOKUP(A7,BBDD!$1:$1048653,11,0) -> Indefinido | G7: =VLOOKUP(A7,BBDD!$1:$1048653,13,0) -> Coronel Rol Tierra | H7: =VLOOKUP(A7,BBDD!$1:$1048653,14,0) -> Gerencia Corp. Negocio Seafood | I7: =VLOOKUP(A7,BBDD!$1:$1048653,16,0) -> Rol General (Cargo permanente o proyección indefinido) | J7: =VLOOKUP(A7,BBDD!$1:$1048653,17,0) | K7: =VLOOKUP(A7,BBDD!$1:$1048653,12,0) -> 45303 | L7: =VLOOKUP(A7,BBDD!$1:$1048653,3,0) -> Orizon S.A | M7: =VLOOKUP(A7,BBDD!$1:$1048653,4,0) -> F1 | N7: =VLOOKUP(A7,BBDD!$1:$1048653,5,0) -> andreanicolecontrerasalegria@gmail.com | O7: 45953 | P7: Teléfono | Q7: Asignación Familiar | R7: Incorporar carga | T7: Cerrado
A8: 18383966 | B8: =VLOOKUP(A8,BBDD!$1:$1048653,2,0) -> 18.383.966-7 | C8: =VLOOKUP(A8,BBDD!$1:$1048653,7,0) -> Riffo Contreras Gabriela Andrea | D8: =VLOOKUP(A8,BBDD!$1:$1048653,8,0) -> Administrativo(A) Prod Sap Y Sernapesca | E8: =VLOOKUP(A8,BBDD!$1:$1048653,10,0) -> Gerencia Producción Pesca | F8: =VLOOKUP(A8,BBDD!$1:$1048653,11,0) -> Indefinido | G8: =VLOOKUP(A8,BBDD!$1:$1048653,13,0) -> Coronel Rol Tierra | H8: =VLOOKUP(A8,BBDD!$1:$1048653,14,0) -> Gerencia Corp. Negocio Seafood | I8: =VLOOKUP(A8,BBDD!$1:$1048653,16,0) -> Rol General (Cargo permanente o proyección indefinido) | J8: =VLOOKUP(A8,BBDD!$1:$1048653,17,0) | K8: =VLOOKUP(A8,BBDD!$1:$1048653,12,0) -> 44553 | L8: =VLOOKUP(A8,BBDD!$1:$1048653,3,0) -> Orizon S.A | M8: =VLOOKUP(A8,BBDD!$1:$1048653,4,0) -> F1 | N8: =VLOOKUP(A8,BBDD!$1:$1048653,5,0) -> gabriela.riffo@orizon.cl | O8: 45953 | P8: Teléfono | Q8: Asignación Familiar | R8: Incorporar carga | T8: Cerrado
A9: 10117554 | B9: =VLOOKUP(A9,BBDD!$1:$1048653,2,0) -> 10.117.554-5 | C9: =VLOOKUP(A9,BBDD!$1:$1048653,7,0) -> Torres Torres Marcelo | D9: =VLOOKUP(A9,BBDD!$1:$1048653,8,0) -> Mecanico De Turno | E9: =VLOOKUP(A9,BBDD!$1:$1048653,10,0) -> Departamento Ingeniería | F9: =VLOOKUP(A9,BBDD!$1:$1048653,11,0) -> Indefinido | G9: =VLOOKUP(A9,BBDD!$1:$1048653,13,0) -> Coronel Rol Tierra | H9: =VLOOKUP(A9,BBDD!$1:$1048653,14,0) -> Gerencia Corp. Negocio Seafood | I9: =VLOOKUP(A9,BBDD!$1:$1048653,16,0) -> Rol General (Cargo permanente o proyección indefinido) | J9: =VLOOKUP(A9,BBDD!$1:$1048653,17,0) | K9: =VLOOKUP(A9,BBDD!$1:$1048653,12,0) -> 44525 | L9: =VLOOKUP(A9,BBDD!$1:$1048653,3,0) -> Orizon S.A | M9: =VLOOKUP(A9,BBDD!$1:$1048653,4,0) -> F1 | N9: =VLOOKUP(A9,BBDD!$1:$1048653,5,0) -> torres.marceloalejandro@gmail.com | O9: 45953 | P9: Teléfono | Q9: Beneficios | R9: Solicita mochila | T9: Cerrado
A10: 16348510 | B10: =VLOOKUP(A10,BBDD!$1:$1048653,2,0) -> 16.348.510-9 | C10: =VLOOKUP(A10,BBDD!$1:$1048653,7,0) -> Jara Gallardo Jose Miguel | D10: =VLOOKUP(A10,BBDD!$1:$1048653,8,0) -> Encargado De Trazabilidad Y Sistema De Pesaje | E10: =VLOOKUP(A10,BBDD!$1:$1048653,10,0) -> Gerencia Producción Pesca | F10: =VLOOKUP(A10,BBDD!$1:$1048653,11,0) -> Indefinido | G10: =VLOOKUP(A10,BBDD!$1:$1048653,13,0) -> Coronel Rol Tierra | H10: =VLOOKUP(A10,BBDD!$1:$1048653,14,0) -> Gerencia Corp. Negocio Seafood | I10: =VLOOKUP(A10,BBDD!$1:$1048653,16,0) -> Rol General (Cargo permanente o proyección indefinido) | J10: =VLOOKUP(A10,BBDD!$1:$1048653,17,0) | K10: =VLOOKUP(A10,BBDD!$1:$1048653,12,0) -> 41659 | L10: =VLOOKUP(A10,BBDD!$1:$1048653,3,0) -> Orizon S.A | M10: =VLOOKUP(A10,BBDD!$1:$1048653,4,0) -> F1 | N10: =VLOOKUP(A10,BBDD!$1:$1048653,5,0) -> jose.jara@orizon.cl | O10: 45953 | P10: Teléfono | Q10: Buk | T10: Cerrado
A11: 11353351 | B11: =VLOOKUP(A11,BBDD!$1:$1048653,2,0) -> 11.353.351-k | C11: =VLOOKUP(A11,BBDD!$1:$1048653,7,0) -> Guevara Letelier Narciso Wilfredo | D11: =VLOOKUP(A11,BBDD!$1:$1048653,8,0) -> Logistico Intermedio | E11: =VLOOKUP(A11,BBDD!$1:$1048653,10,0) -> Gerencia Abastecimiento | F11: =VLOOKUP(A11,BBDD!$1:$1048653,11,0) -> Indefinido | G11: =VLOOKUP(A11,BBDD!$1:$1048653,13,0) -> Coronel Rol Tierra | H11: =VLOOKUP(A11,BBDD!$1:$1048653,14,0) -> Gerencia Corp. Supply Chain | I11: =VLOOKUP(A11,BBDD!$1:$1048653,16,0) -> Rol General (Cargo permanente o proyección indefinido) | J11: =VLOOKUP(A11,BBDD!$1:$1048653,17,0) | K11: =VLOOKUP(A11,BBDD!$1:$1048653,12,0) -> 40513 | L11: =VLOOKUP(A11,BBDD!$1:$1048653,3,0) -> Orizon S.A | M11: =VLOOKUP(A11,BBDD!$1:$1048653,4,0) -> F1 | N11: =VLOOKUP(A11,BBDD!$1:$1048653,5,0) -> narciso.guevara@orizon.cl | O11: 45953 | P11: Teléfono | Q11: Reclutamiento y Selección | T11: Cerrado
A12: 9753137 | B12: =VLOOKUP(A12,BBDD!$1:$1048653,2,0) -> 9.753.137-4 | C12: =VLOOKUP(A12,BBDD!$1:$1048653,7,0) -> Manriquez Duran Fabian Gustavo | D12: =VLOOKUP(A12,BBDD!$1:$1048653,8,0) -> Contramaestre | E12: =VLOOKUP(A12,BBDD!$1:$1048653,10,0) -> Gerencia de Flota y Abastecimiento de Materias Primas | F12: =VLOOKUP(A12,BBDD!$1:$1048653,11,0) -> Indefinido | G12: =VLOOKUP(A12,BBDD!$1:$1048653,13,0) -> Coronel Rol Flota | H12: =VLOOKUP(A12,BBDD!$1:$1048653,14,0) -> Gerencia Corp. Negocio Seafood | I12: =VLOOKUP(A12,BBDD!$1:$1048653,16,0) -> Rol General (Cargo permanente o proyección indefinido) | J12: =VLOOKUP(A12,BBDD!$1:$1048653,17,0) | K12: =VLOOKUP(A12,BBDD!$1:$1048653,12,0) -> 40513 | L12: =VLOOKUP(A12,BBDD!$1:$1048653,3,0) -> Orizon S.A | M12: =VLOOKUP(A12,BBDD!$1:$1048653,4,0) -> F1 | N12: =VLOOKUP(A12,BBDD!$1:$1048653,5,0) -> fmanriquezd@gmail.com | O12: 45953 | P12: Teléfono | Q12: Seguro de Salud | R12: Consulta por tripulante Felix Toledo | T12: Cerrado
A13: 1 | B13: =VLOOKUP(A13,BBDD!$1:$1048653,2,0) -> Usuario Externo | C13: =VLOOKUP(A13,BBDD!$1:$1048653,7,0) -> Usuario Externo | D13: =VLOOKUP(A13,BBDD!$1:$1048653,8,0) -> Usuario Externo | E13: =VLOOKUP(A13,BBDD!$1:$1048653,10,0) -> Usuario Externo | F13: =VLOOKUP(A13,BBDD!$1:$1048653,11,0) -> Usuario Externo | G13: =VLOOKUP(A13,BBDD!$1:$1048653,13,0) -> Usuario Externo | H13: =VLOOKUP(A13,BBDD!$1:$1048653,14,0) -> Usuario Externo | I13: =VLOOKUP(A13,BBDD!$1:$1048653,16,0) -> Usuario Externo | J13: =VLOOKUP(A13,BBDD!$1:$1048653,17,0) | K13: =VLOOKUP(A13,BBDD!$1:$1048653,12,0) -> Usuario Externo | L13: =VLOOKUP(A13,BBDD!$1:$1048653,3,0) -> Usuario Externo | M13: =VLOOKUP(A13,BBDD!$1:$1048653,4,0) -> Usuario Externo | N13: =VLOOKUP(A13,BBDD!$1:$1048653,5,0) -> Usuario Externo | O13: 45953 | P13: Oficina | Q13: Reclutamiento y Selección | T13: Cerrado
A14: 1 | B14: =VLOOKUP(A14,BBDD!$1:$1048653,2,0) -> Usuario Externo | C14: =VLOOKUP(A14,BBDD!$1:$1048653,7,0) -> Usuario Externo | D14: =VLOOKUP(A14,BBDD!$1:$1048653,8,0) -> Usuario Externo | E14: =VLOOKUP(A14,BBDD!$1:$1048653,10,0) -> Usuario Externo | F14: =VLOOKUP(A14,BBDD!$1:$1048653,11,0) -> Usuario Externo | G14: =VLOOKUP(A14,BBDD!$1:$1048653,13,0) -> Usuario Externo | H14: =VLOOKUP(A14,BBDD!$1:$1048653,14,0) -> Usuario Externo | I14: =VLOOKUP(A14,BBDD!$1:$1048653,16,0) -> Usuario Externo | J14: =VLOOKUP(A14,BBDD!$1:$1048653,17,0) | K14: =VLOOKUP(A14,BBDD!$1:$1048653,12,0) -> Usuario Externo | L14: =VLOOKUP(A14,BBDD!$1:$1048653,3,0) -> Usuario Externo | M14: =VLOOKUP(A14,BBDD!$1:$1048653,4,0) -> Usuario Externo | N14: =VLOOKUP(A14,BBDD!$1:$1048653,5,0) -> Usuario Externo | O14: 45953 | P14: Oficina | Q14: Documentos | T14: Cerrado
A15: 1 | B15: =VLOOKUP(A15,BBDD!$1:$1048653,2,0) -> Usuario Externo | C15: =VLOOKUP(A15,BBDD!$1:$1048653,7,0) -> Usuario Externo | D15: =VLOOKUP(A15,BBDD!$1:$1048653,8,0) -> Usuario Externo | E15: =VLOOKUP(A15,BBDD!$1:$1048653,10,0) -> Usuario Externo | F15: =VLOOKUP(A15,BBDD!$1:$1048653,11,0) -> Usuario Externo | G15: =VLOOKUP(A15,BBDD!$1:$1048653,13,0) -> Usuario Externo | H15: =VLOOKUP(A15,BBDD!$1:$1048653,14,0) -> Usuario Externo | I15: =VLOOKUP(A15,BBDD!$1:$1048653,16,0) -> Usuario Externo | J15: =VLOOKUP(A15,BBDD!$1:$1048653,17,0) | K15: =VLOOKUP(A15,BBDD!$1:$1048653,12,0) -> Usuario Externo | L15: =VLOOKUP(A15,BBDD!$1:$1048653,3,0) -> Usuario Externo | M15: =VLOOKUP(A15,BBDD!$1:$1048653,4,0) -> Usuario Externo | N15: =VLOOKUP(A15,BBDD!$1:$1048653,5,0) -> Usuario Externo | O15: 45953 | P15: Teléfono | Q15: Beneficios | R15: Solicitud agenda Nutrisco Chile | T15: Cerrado
A16: 20195336 | B16: =VLOOKUP(A16,BBDD!$1:$1048653,2,0) -> 20.195.336-7 | C16: =VLOOKUP(A16,BBDD!$1:$1048653,7,0) -> Cabrera Ortega Carolina Belen | D16: =VLOOKUP(A16,BBDD!$1:$1048653,8,0) -> Asistente Operaciones Pt | E16: =VLOOKUP(A16,BBDD!$1:$1048653,10,0) -> Gerencia Logistica | F16: =VLOOKUP(A16,BBDD!$1:$1048653,11,0) -> Plazo fijo | G16: =VLOOKUP(A16,BBDD!$1:$1048653,13,0) -> Coronel Rol Tierra | H16: =VLOOKUP(A16,BBDD!$1:$1048653,14,0) -> Gerencia Corp. Supply Chain | I16: =VLOOKUP(A16,BBDD!$1:$1048653,16,0) -> Temporada (Con ocasión Temporada de Pesca) | J16: =VLOOKUP(A16,BBDD!$1:$1048653,17,0) | K16: =VLOOKUP(A16,BBDD!$1:$1048653,12,0) -> 45936 | L16: =VLOOKUP(A16,BBDD!$1:$1048653,3,0) -> Orizon S.A | M16: =VLOOKUP(A16,BBDD!$1:$1048653,4,0) -> F2 | N16: =VLOOKUP(A16,BBDD!$1:$1048653,5,0) -> carolinacabreraortega@gmail.com | O16: 45953 | P16: Teléfono | Q16: Finiquito | S16: Transferencia realizada | T16: Cerrado
A17: 15170747 | B17: =VLOOKUP(A17,BBDD!$1:$1048653,2,0) -> 15.170.747-5 | C17: =VLOOKUP(A17,BBDD!$1:$1048653,7,0) -> Hidalgo Alarcon Christian Alejandro | D17: =VLOOKUP(A17,BBDD!$1:$1048653,8,0) -> Mecanico De Turno | E17: =VLOOKUP(A17,BBDD!$1:$1048653,10,0) -> Departamento Ingeniería | F17: =VLOOKUP(A17,BBDD!$1:$1048653,11,0) -> Indefinido | G17: =VLOOKUP(A17,BBDD!$1:$1048653,13,0) -> Coronel Rol Tierra | H17: =VLOOKUP(A17,BBDD!$1:$1048653,14,0) -> Gerencia Corp. Negocio Seafood | I17: =VLOOKUP(A17,BBDD!$1:$1048653,16,0) -> Rol General (Cargo permanente o proyección indefinido) | J17: =VLOOKUP(A17,BBDD!$1:$1048653,17,0) | K17: =VLOOKUP(A17,BBDD!$1:$1048653,12,0) -> 45397 | L17: =VLOOKUP(A17,BBDD!$1:$1048653,3,0) -> Orizon S.A | M17: =VLOOKUP(A17,BBDD!$1:$1048653,4,0) -> F1 | N17: =VLOOKUP(A17,BBDD!$1:$1048653,5,0) -> CHRISTIANALEJ28@GMAIL.COM | O17: 45953 | P17: Oficina | Q17: Beneficios | R17: No puede ingresar link regalo | T17: Cerrado
A18: 15194019 | B18: =VLOOKUP(A18,BBDD!$1:$1048653,2,0) -> 15.194.019-6 | C18: =VLOOKUP(A18,BBDD!$1:$1048653,7,0) -> Rojas Olate Alejandro Humberto | D18: =VLOOKUP(A18,BBDD!$1:$1048653,8,0) -> Administrativo(A) Prod Sap Y Sernapesca | E18: =VLOOKUP(A18,BBDD!$1:$1048653,10,0) -> Gerencia Producción Pesca | F18: =VLOOKUP(A18,BBDD!$1:$1048653,11,0) -> Indefinido | G18: =VLOOKUP(A18,BBDD!$1:$1048653,13,0) -> Coronel Rol Tierra | H18: =VLOOKUP(A18,BBDD!$1:$1048653,14,0) -> Gerencia Corp. Negocio Seafood | I18: =VLOOKUP(A18,BBDD!$1:$1048653,16,0) -> Rol General (Cargo permanente o proyección indefinido) | J18: =VLOOKUP(A18,BBDD!$1:$1048653,17,0) | K18: =VLOOKUP(A18,BBDD!$1:$1048653,12,0) -> 42795 | L18: =VLOOKUP(A18,BBDD!$1:$1048653,3,0) -> Orizon S.A | M18: =VLOOKUP(A18,BBDD!$1:$1048653,4,0) -> F1 | N18: =VLOOKUP(A18,BBDD!$1:$1048653,5,0) -> Alejandro.Rojas@orizon.cl | O18: 45953 | P18: Oficina | Q18: Reclutamiento y Selección | T18: Cerrado
A19: 19532216 | B19: =VLOOKUP(A19,BBDD!$1:$1048653,2,0) -> 19.532.216-3 | C19: =VLOOKUP(A19,BBDD!$1:$1048653,7,0) -> Gonzalez Guiñez Cristopher Distefano | D19: =VLOOKUP(A19,BBDD!$1:$1048653,8,0) -> Operario Apoyo Elaboracion | E19: =VLOOKUP(A19,BBDD!$1:$1048653,10,0) -> Gerencia Producción Pesca | F19: =VLOOKUP(A19,BBDD!$1:$1048653,11,0) -> Plazo fijo | G19: =VLOOKUP(A19,BBDD!$1:$1048653,13,0) -> Coronel Rol Eventual | H19: =VLOOKUP(A19,BBDD!$1:$1048653,14,0) -> Gerencia Corp. Negocio Seafood | I19: =VLOOKUP(A19,BBDD!$1:$1048653,16,0) -> Temporada (Con ocasión Temporada de Pesca) | J19: =VLOOKUP(A19,BBDD!$1:$1048653,17,0) | K19: =VLOOKUP(A19,BBDD!$1:$1048653,12,0) -> 45931 | L19: =VLOOKUP(A19,BBDD!$1:$1048653,3,0) -> Orizon S.A | M19: =VLOOKUP(A19,BBDD!$1:$1048653,4,0) -> F5 | N19: =VLOOKUP(A19,BBDD!$1:$1048653,5,0) -> crisgonzalez@cftla.cl | O19: 45953 | P19: Oficina | Q19: Remuneraciones | R19: Cambio cuenta bancaria | T19: Cerrado
A20: 18414706 | B20: =VLOOKUP(A20,BBDD!$1:$1048653,2,0) -> 18.414.706-8 | C20: =VLOOKUP(A20,BBDD!$1:$1048653,7,0) -> Zapata Gutierrez Dieter Ismael | D20: =VLOOKUP(A20,BBDD!$1:$1048653,8,0) -> Laboratorista Aseguramiento Calidad | E20: =VLOOKUP(A20,BBDD!$1:$1048653,10,0) -> Gerencia Gestión Integrada y Calidad | F20: =VLOOKUP(A20,BBDD!$1:$1048653,11,0) -> Plazo fijo | G20: =VLOOKUP(A20,BBDD!$1:$1048653,13,0) -> Coronel Rol Tierra | H20: =VLOOKUP(A20,BBDD!$1:$1048653,14,0) -> Gerencia Corp. Negocio Seafood | I20: =VLOOKUP(A20,BBDD!$1:$1048653,16,0) -> Temporada (Con ocasión Temporada de Pesca) | J20: =VLOOKUP(A20,BBDD!$1:$1048653,17,0) | K20: =VLOOKUP(A20,BBDD!$1:$1048653,12,0) -> 45933 | L20: =VLOOKUP(A20,BBDD!$1:$1048653,3,0) -> Orizon S.A | M20: =VLOOKUP(A20,BBDD!$1:$1048653,4,0) -> F4 | N20: =VLOOKUP(A20,BBDD!$1:$1048653,5,0) -> DIETER.ZAPATA@GMAIL.COM | O20: 45953 | P20: Oficina | Q20: Contrato | R20: Cargar en Buk | S20: Contrato cargado Milton y Dieter ok | T20: Cerrado
A21: 15196579 | B21: =VLOOKUP(A21,BBDD!$1:$1048653,2,0) -> 15.196.579-2 | C21: =VLOOKUP(A21,BBDD!$1:$1048653,7,0) -> Huerta Miranda Mirian Andrea | D21: =VLOOKUP(A21,BBDD!$1:$1048653,8,0) -> Operario Apoyo Elaboracion | E21: =VLOOKUP(A21,BBDD!$1:$1048653,10,0) -> Gerencia Producción Pesca | F21: =VLOOKUP(A21,BBDD!$1:$1048653,11,0) -> Plazo fijo | G21: =VLOOKUP(A21,BBDD!$1:$1048653,13,0) -> Coronel Rol Eventual | H21: =VLOOKUP(A21,BBDD!$1:$1048653,14,0) -> Gerencia Corp. Negocio Seafood | I21: =VLOOKUP(A21,BBDD!$1:$1048653,16,0) -> Temporada (Con ocasión Temporada de Pesca) | J21: =VLOOKUP(A21,BBDD!$1:$1048653,17,0) | K21: =VLOOKUP(A21,BBDD!$1:$1048653,12,0) -> 45941 | L21: =VLOOKUP(A21,BBDD!$1:$1048653,3,0) -> Orizon S.A | M21: =VLOOKUP(A21,BBDD!$1:$1048653,4,0) -> F1 | N21: =VLOOKUP(A21,BBDD!$1:$1048653,5,0) -> andrehm416@gmail.com | O21: 45953 | P21: Oficina | Q21: Asistencia | T21: Cerrado
A22: 17228845 | B22: 17228845-6 | C22: =VLOOKUP(A22,BBDD!$1:$1048653,7,0) -> Espina Sandoval Debora Alejandra | D22: =VLOOKUP(A22,BBDD!$1:$1048653,8,0) -> Operario Apoyo Elaboracion | E22: =VLOOKUP(A22,BBDD!$1:$1048653,10,0) -> Gerencia Producción Pesca | F22: =VLOOKUP(A22,BBDD!$1:$1048653,11,0) -> Plazo fijo | G22: =VLOOKUP(A22,BBDD!$1:$1048653,13,0) -> Coronel Rol Eventual | H22: =VLOOKUP(A22,BBDD!$1:$1048653,14,0) -> Gerencia Corp. Negocio Seafood | I22: =VLOOKUP(A22,BBDD!$1:$1048653,16,0) -> Temporada (Con ocasión Temporada de Pesca) | J22: =VLOOKUP(A22,BBDD!$1:$1048653,17,0) | K22: =VLOOKUP(A22,BBDD!$1:$1048653,12,0) -> 45941 | L22: =VLOOKUP(A22,BBDD!$1:$1048653,3,0) -> Orizon S.A | M22: =VLOOKUP(A22,BBDD!$1:$1048653,4,0) -> F1 | N22: =VLOOKUP(A22,BBDD!$1:$1048653,5,0) -> espinadebora7@gmail.com | O22: 45953 | P22: Oficina | Q22: Remuneraciones | R22: Cambio cuenta bancaria | S22: Cambio realizado | T22: Cerrado
A23: 21658470 | B23: =VLOOKUP(A23,BBDD!$1:$1048653,2,0) -> 21.658.470-8 | C23: =VLOOKUP(A23,BBDD!$1:$1048653,7,0) -> Aravena Fuentealba Javier Natahel | D23: =VLOOKUP(A23,BBDD!$1:$1048653,8,0) -> Operador Elaboracion Php | E23: =VLOOKUP(A23,BBDD!$1:$1048653,10,0) -> Gerencia Producción Pesca | F23: =VLOOKUP(A23,BBDD!$1:$1048653,11,0) -> Plazo fijo | G23: =VLOOKUP(A23,BBDD!$1:$1048653,13,0) -> Coronel Rol Tierra | H23: =VLOOKUP(A23,BBDD!$1:$1048653,14,0) -> Gerencia Corp. Negocio Seafood | I23: =VLOOKUP(A23,BBDD!$1:$1048653,16,0) -> Temporada (Con ocasión Temporada de Pesca) | J23: =VLOOKUP(A23,BBDD!$1:$1048653,17,0) | K23: =VLOOKUP(A23,BBDD!$1:$1048653,12,0) -> 45933 | L23: =VLOOKUP(A23,BBDD!$1:$1048653,3,0) -> Orizon S.A | M23: =VLOOKUP(A23,BBDD!$1:$1048653,4,0) -> F4 | N23: =VLOOKUP(A23,BBDD!$1:$1048653,5,0) -> JAVIERFUENTEALBA303@GMAIL.COM | O23: 45953 | P23: Oficina | Q23: Contrato | R23: Cargar en Buk | T23: Cerrado
A24: 20512923 | B24: =VLOOKUP(A24,BBDD!$1:$1048653,2,0) -> 20.512.923-5 | C24: =VLOOKUP(A24,BBDD!$1:$1048653,7,0) -> Morales Alvarez Carlos Patricio | D24: =VLOOKUP(A24,BBDD!$1:$1048653,8,0) -> Operario Apoyo Elaboracion | E24: =VLOOKUP(A24,BBDD!$1:$1048653,10,0) -> Gerencia Producción Pesca | F24: =VLOOKUP(A24,BBDD!$1:$1048653,11,0) -> Plazo fijo | G24: =VLOOKUP(A24,BBDD!$1:$1048653,13,0) -> Coronel Rol Eventual | H24: =VLOOKUP(A24,BBDD!$1:$1048653,14,0) -> Gerencia Corp. Negocio Seafood | I24: =VLOOKUP(A24,BBDD!$1:$1048653,16,0) -> Temporada (Con ocasión Temporada de Pesca) | J24: =VLOOKUP(A24,BBDD!$1:$1048653,17,0) | K24: =VLOOKUP(A24,BBDD!$1:$1048653,12,0) -> 45940 | L24: =VLOOKUP(A24,BBDD!$1:$1048653,3,0) -> Orizon S.A | M24: =VLOOKUP(A24,BBDD!$1:$1048653,4,0) -> F2 | N24: =VLOOKUP(A24,BBDD!$1:$1048653,5,0) -> cm0828458@gmail.com | O24: 45953 | P24: Oficina | Q24: Asistencia | R24: No puede marcar | S24: Derivado a control tiempo | T24: Cerrado
A25: 16009687 | B25: =VLOOKUP(A25,BBDD!$1:$1048653,2,0) -> 16.009.687-k | C25: =VLOOKUP(A25,BBDD!$1:$1048653,7,0) -> Muñoz Muñoz Viviana Elizabeth | D25: =VLOOKUP(A25,BBDD!$1:$1048653,8,0) -> Operario Apoyo Elaboracion | E25: =VLOOKUP(A25,BBDD!$1:$1048653,10,0) -> Gerencia Producción Pesca | F25: =VLOOKUP(A25,BBDD!$1:$1048653,11,0) -> Plazo fijo | G25: =VLOOKUP(A25,BBDD!$1:$1048653,13,0) -> Coronel Rol Eventual | H25: =VLOOKUP(A25,BBDD!$1:$1048653,14,0) -> Gerencia Corp. Negocio Seafood | I25: =VLOOKUP(A25,BBDD!$1:$1048653,16,0) -> Temporada (Con ocasión Temporada de Pesca) | J25: =VLOOKUP(A25,BBDD!$1:$1048653,17,0) | K25: =VLOOKUP(A25,BBDD!$1:$1048653,12,0) -> 45942 | L25: =VLOOKUP(A25,BBDD!$1:$1048653,3,0) -> Orizon S.A | M25: =VLOOKUP(A25,BBDD!$1:$1048653,4,0) -> F3 | N25: =VLOOKUP(A25,BBDD!$1:$1048653,5,0) -> x.abrazame@hotmail.com | O25: 45953 | P25: Oficina | Q25: Asignación Familiar | R25: Incorporación de carga | S25: Pendiente documentación trbajador | T25: Abierto
A26: 27046927 | B26: =VLOOKUP(A26,BBDD!$1:$1048653,2,0) -> 27.046.927-2 | C26: =VLOOKUP(A26,BBDD!$1:$1048653,7,0) -> Colina Atacho Henyerber Jose | D26: =VLOOKUP(A26,BBDD!$1:$1048653,8,0) -> Operario Apoyo Elaboracion | E26: =VLOOKUP(A26,BBDD!$1:$1048653,10,0) -> Gerencia Producción Pesca | F26: =VLOOKUP(A26,BBDD!$1:$1048653,11,0) -> Plazo fijo | G26: =VLOOKUP(A26,BBDD!$1:$1048653,13,0) -> Coronel Rol Eventual | H26: =VLOOKUP(A26,BBDD!$1:$1048653,14,0) -> Gerencia Corp. Negocio Seafood | I26: =VLOOKUP(A26,BBDD!$1:$1048653,16,0) -> Temporada (Con ocasión Temporada de Pesca) | J26: =VLOOKUP(A26,BBDD!$1:$1048653,17,0) | K26: =VLOOKUP(A26,BBDD!$1:$1048653,12,0) -> 45931 | L26: =VLOOKUP(A26,BBDD!$1:$1048653,3,0) -> Orizon S.A | M26: =VLOOKUP(A26,BBDD!$1:$1048653,4,0) -> F2 | N26: =VLOOKUP(A26,BBDD!$1:$1048653,5,0) -> chuchocolina@gmail.com | O26: 45953 | P26: Oficina | Q26: Asistencia | R26: No puede marcar reloj de la consera | S26: Seguira marcando en reloj del hall | T26: Cerrado
A27: 20785939 | B27: =VLOOKUP(A27,BBDD!$1:$1048653,2,0) -> 20.785.939-7 | C27: =VLOOKUP(A27,BBDD!$1:$1048653,7,0) -> Palma Elevancin Hector Juan Pablo | D27: =VLOOKUP(A27,BBDD!$1:$1048653,8,0) -> Operador Control Producción | E27: =VLOOKUP(A27,BBDD!$1:$1048653,10,0) -> Gerencia Producción Pesca | F27: =VLOOKUP(A27,BBDD!$1:$1048653,11,0) -> Plazo fijo | G27: =VLOOKUP(A27,BBDD!$1:$1048653,13,0) -> Coronel Rol Eventual | H27: =VLOOKUP(A27,BBDD!$1:$1048653,14,0) -> Gerencia Corp. Negocio Seafood | I27: =VLOOKUP(A27,BBDD!$1:$1048653,16,0) -> Temporada (Con ocasión Temporada de Pesca) | J27: =VLOOKUP(A27,BBDD!$1:$1048653,17,0) | K27: =VLOOKUP(A27,BBDD!$1:$1048653,12,0) -> 45950 | L27: =VLOOKUP(A27,BBDD!$1:$1048653,3,0) -> Orizon S.A | M27: =VLOOKUP(A27,BBDD!$1:$1048653,4,0) -> F1 | N27: =VLOOKUP(A27,BBDD!$1:$1048653,5,0) -> Palmaelevancin0@gmail.com | O27: 45953 | P27: Oficina | Q27: Contrato | T27: Cerrado
A28: 17571642 | B28: =VLOOKUP(A28,BBDD!$1:$1048653,2,0) -> 17.571.642-4 | C28: =VLOOKUP(A28,BBDD!$1:$1048653,7,0) -> Bermedo Vargas Ninoska Alejandra | D28: =VLOOKUP(A28,BBDD!$1:$1048653,8,0) -> Operario Apoyo Elaboracion | E28: =VLOOKUP(A28,BBDD!$1:$1048653,10,0) -> Gerencia Producción Pesca | F28: =VLOOKUP(A28,BBDD!$1:$1048653,11,0) -> Plazo fijo | G28: =VLOOKUP(A28,BBDD!$1:$1048653,13,0) -> Coronel Rol Eventual | H28: =VLOOKUP(A28,BBDD!$1:$1048653,14,0) -> Gerencia Corp. Negocio Seafood | I28: =VLOOKUP(A28,BBDD!$1:$1048653,16,0) -> Temporada (Con ocasión Temporada de Pesca) | J28: =VLOOKUP(A28,BBDD!$1:$1048653,17,0) | K28: =VLOOKUP(A28,BBDD!$1:$1048653,12,0) -> 45931 | L28: =VLOOKUP(A28,BBDD!$1:$1048653,3,0) -> Orizon S.A | M28: =VLOOKUP(A28,BBDD!$1:$1048653,4,0) -> F4 | N28: =VLOOKUP(A28,BBDD!$1:$1048653,5,0) -> nino.bermedo@hotmail.com | O28: 45953 | P28: E-mail | Q28: Asistencia | R28: Trabajador informa de ausencia por asalto mientras iba a tomar transporte | S28: PSG ,dja constacia en carabineros | T28: Cerrado
A29: 1 | B29: =VLOOKUP(A29,BBDD!$1:$1048653,2,0) -> Usuario Externo | C29: =VLOOKUP(A29,BBDD!$1:$1048653,7,0) -> Usuario Externo | D29: =VLOOKUP(A29,BBDD!$1:$1048653,8,0) -> Usuario Externo | E29: =VLOOKUP(A29,BBDD!$1:$1048653,10,0) -> Usuario Externo | F29: =VLOOKUP(A29,BBDD!$1:$1048653,11,0) -> Usuario Externo | G29: =VLOOKUP(A29,BBDD!$1:$1048653,13,0) -> Usuario Externo | H29: =VLOOKUP(A29,BBDD!$1:$1048653,14,0) -> Usuario Externo | I29: =VLOOKUP(A29,BBDD!$1:$1048653,16,0) -> Usuario Externo | J29: =VLOOKUP(A29,BBDD!$1:$1048653,17,0) | K29: =VLOOKUP(A29,BBDD!$1:$1048653,12,0) -> Usuario Externo | L29: =VLOOKUP(A29,BBDD!$1:$1048653,3,0) -> Usuario Externo | M29: =VLOOKUP(A29,BBDD!$1:$1048653,4,0) -> Usuario Externo | N29: =VLOOKUP(A29,BBDD!$1:$1048653,5,0) -> Usuario Externo | O29: 45953 | P29: Teléfono | Q29: Otro | R29: Trabajador informa que aplicación de buk le señala Adriana Katherine | T29: Abierto
A30: 14361771 | B30: =VLOOKUP(A30,BBDD!$1:$1048653,2,0) -> 14.361.771-8 | C30: =VLOOKUP(A30,BBDD!$1:$1048653,7,0) -> Flores Abarca Araceli De Las Mercedes | D30: =VLOOKUP(A30,BBDD!$1:$1048653,8,0) -> Operario Apoyo Elaboracion | E30: =VLOOKUP(A30,BBDD!$1:$1048653,10,0) -> Gerencia Producción Pesca | F30: =VLOOKUP(A30,BBDD!$1:$1048653,11,0) -> Plazo fijo | G30: =VLOOKUP(A30,BBDD!$1:$1048653,13,0) -> Coronel Rol Eventual | H30: =VLOOKUP(A30,BBDD!$1:$1048653,14,0) -> Gerencia Corp. Negocio Seafood | I30: =VLOOKUP(A30,BBDD!$1:$1048653,16,0) -> Temporada (Con ocasión Temporada de Pesca) | J30: =VLOOKUP(A30,BBDD!$1:$1048653,17,0) | K30: =VLOOKUP(A30,BBDD!$1:$1048653,12,0) -> 45931 | L30: =VLOOKUP(A30,BBDD!$1:$1048653,3,0) -> Orizon S.A | M30: =VLOOKUP(A30,BBDD!$1:$1048653,4,0) -> F3 | N30: =VLOOKUP(A30,BBDD!$1:$1048653,5,0) -> araceli.10abarca@gmail.com | O30: 45954 | P30: Oficina | Q30: Asistencia | R30: Entrega documeto por inasistencia | T30: Cerrado
A31: 20613170 | B31: =VLOOKUP(A31,BBDD!$1:$1048653,2,0) -> 20.613.170-5 | C31: =VLOOKUP(A31,BBDD!$1:$1048653,7,0) -> Carrasco Copelli Valentin Patricio | D31: =VLOOKUP(A31,BBDD!$1:$1048653,8,0) -> Operador De Autoclaves | E31: =VLOOKUP(A31,BBDD!$1:$1048653,10,0) -> Gerencia Producción Pesca | F31: =VLOOKUP(A31,BBDD!$1:$1048653,11,0) -> Indefinido | G31: =VLOOKUP(A31,BBDD!$1:$1048653,13,0) -> Coronel Rol Tierra | H31: =VLOOKUP(A31,BBDD!$1:$1048653,14,0) -> Gerencia Corp. Negocio Seafood | I31: =VLOOKUP(A31,BBDD!$1:$1048653,16,0) -> Rol General (Cargo permanente o proyección indefinido) | J31: =VLOOKUP(A31,BBDD!$1:$1048653,17,0) | K31: =VLOOKUP(A31,BBDD!$1:$1048653,12,0) -> 44531 | L31: =VLOOKUP(A31,BBDD!$1:$1048653,3,0) -> Orizon S.A | M31: =VLOOKUP(A31,BBDD!$1:$1048653,4,0) -> F1 | N31: =VLOOKUP(A31,BBDD!$1:$1048653,5,0) -> valentincarrascocopelli1010@gmail.com | O31: 45954 | P31: Oficina | Q31: Asistencia | T31: Cerrado
A32: 1 | B32: =VLOOKUP(A32,BBDD!$1:$1048653,2,0) -> Usuario Externo | C32: =VLOOKUP(A32,BBDD!$1:$1048653,7,0) -> Usuario Externo | D32: =VLOOKUP(A32,BBDD!$1:$1048653,8,0) -> Usuario Externo | E32: =VLOOKUP(A32,BBDD!$1:$1048653,10,0) -> Usuario Externo | F32: =VLOOKUP(A32,BBDD!$1:$1048653,11,0) -> Usuario Externo | G32: =VLOOKUP(A32,BBDD!$1:$1048653,13,0) -> Usuario Externo | H32: =VLOOKUP(A32,BBDD!$1:$1048653,14,0) -> Usuario Externo | I32: =VLOOKUP(A32,BBDD!$1:$1048653,16,0) -> Usuario Externo | J32: =VLOOKUP(A32,BBDD!$1:$1048653,17,0) | K32: =VLOOKUP(A32,BBDD!$1:$1048653,12,0) -> Usuario Externo | L32: =VLOOKUP(A32,BBDD!$1:$1048653,3,0) -> Usuario Externo | M32: =VLOOKUP(A32,BBDD!$1:$1048653,4,0) -> Usuario Externo | N32: =VLOOKUP(A32,BBDD!$1:$1048653,5,0) -> Usuario Externo | O32: 45954 | P32: Oficina | Q32: Asistencia | T32: Cerrado
A33: 1 | B33: =VLOOKUP(A33,BBDD!$1:$1048653,2,0) -> Usuario Externo | C33: =VLOOKUP(A33,BBDD!$1:$1048653,7,0) -> Usuario Externo | D33: =VLOOKUP(A33,BBDD!$1:$1048653,8,0) -> Usuario Externo | E33: =VLOOKUP(A33,BBDD!$1:$1048653,10,0) -> Usuario Externo | F33: =VLOOKUP(A33,BBDD!$1:$1048653,11,0) -> Usuario Externo | G33: =VLOOKUP(A33,BBDD!$1:$1048653,13,0) -> Usuario Externo | H33: =VLOOKUP(A33,BBDD!$1:$1048653,14,0) -> Usuario Externo | I33: =VLOOKUP(A33,BBDD!$1:$1048653,16,0) -> Usuario Externo | J33: =VLOOKUP(A33,BBDD!$1:$1048653,17,0) | K33: =VLOOKUP(A33,BBDD!$1:$1048653,12,0) -> Usuario Externo | L33: =VLOOKUP(A33,BBDD!$1:$1048653,3,0) -> Usuario Externo | M33: =VLOOKUP(A33,BBDD!$1:$1048653,4,0) -> Usuario Externo | N33: =VLOOKUP(A33,BBDD!$1:$1048653,5,0) -> Usuario Externo | O33: 45954 | P33: Oficina | Q33: Contrato | R33: Pendiente Jonathan Mella | T33: Abierto
A34: 17690284 | B34: =VLOOKUP(A34,BBDD!$1:$1048653,2,0) -> 17.690.284-1 | C34: =VLOOKUP(A34,BBDD!$1:$1048653,7,0) -> Navarro Marmiez Stephanie Nicole | D34: =VLOOKUP(A34,BBDD!$1:$1048653,8,0) -> Encargado(A) Logistico I | E34: =VLOOKUP(A34,BBDD!$1:$1048653,10,0) -> Gerencia Logistica | F34: =VLOOKUP(A34,BBDD!$1:$1048653,11,0) -> Indefinido | G34: =VLOOKUP(A34,BBDD!$1:$1048653,13,0) -> Coronel Rol Tierra | H34: =VLOOKUP(A34,BBDD!$1:$1048653,14,0) -> Gerencia Corp. Supply Chain | I34: =VLOOKUP(A34,BBDD!$1:$1048653,16,0) -> Rol General (Cargo permanente o proyección indefinido) | J34: =VLOOKUP(A34,BBDD!$1:$1048653,17,0) | K34: =VLOOKUP(A34,BBDD!$1:$1048653,12,0) -> 42736 | L34: =VLOOKUP(A34,BBDD!$1:$1048653,3,0) -> Orizon S.A | M34: =VLOOKUP(A34,BBDD!$1:$1048653,4,0) -> F1 | N34: =VLOOKUP(A34,BBDD!$1:$1048653,5,0) -> stephanie.navarro@orizon.cl | O34: 45954 | P34: Oficina | Q34: Credencial | R34: Solicita Credencial para su equipo, no hay impresora | S34: Esperar a que lleguen insumos y actualizar sus fotos de equipo | T34: Abierto
A35: 10072688 | B35: =VLOOKUP(A35,BBDD!$1:$1048653,2,0) -> 10.072.688-2 | C35: =VLOOKUP(A35,BBDD!$1:$1048653,7,0) -> Bustos Delgado Elbert Billy | D35: =VLOOKUP(A35,BBDD!$1:$1048653,8,0) -> Tripulante | E35: =VLOOKUP(A35,BBDD!$1:$1048653,10,0) -> Gerencia de Flota y Abastecimiento de Materias Primas | F35: =VLOOKUP(A35,BBDD!$1:$1048653,11,0) -> Indefinido | G35: =VLOOKUP(A35,BBDD!$1:$1048653,13,0) -> Coronel Rol Flota | H35: =VLOOKUP(A35,BBDD!$1:$1048653,14,0) -> Gerencia Corp. Negocio Seafood | I35: =VLOOKUP(A35,BBDD!$1:$1048653,16,0) -> Rol General (Cargo permanente o proyección indefinido) | J35: =VLOOKUP(A35,BBDD!$1:$1048653,17,0) | K35: =VLOOKUP(A35,BBDD!$1:$1048653,12,0) -> 45603 | L35: =VLOOKUP(A35,BBDD!$1:$1048653,3,0) -> Orizon S.A | M35: =VLOOKUP(A35,BBDD!$1:$1048653,4,0) -> F1 | N35: =VLOOKUP(A35,BBDD!$1:$1048653,5,0) -> billylosrios2@gmail.com | O35: 45954 | P35: Oficina | Q35: Seguro de Salud | R35: Solicita informacion de beneficios y incorporacion del seguro | S35: se envio informacion para incorporacion a euroamerica | T35: Abierto
A36: 12703195 | B36: =VLOOKUP(A36,BBDD!$1:$1048653,2,0) -> 12.703.195-9 | C36: =VLOOKUP(A36,BBDD!$1:$1048653,7,0) -> Rios Soto Angelo Enrique | D36: =VLOOKUP(A36,BBDD!$1:$1048653,8,0) -> Monitor(A) De Calidad | E36: =VLOOKUP(A36,BBDD!$1:$1048653,10,0) -> Gerencia Gestión Integrada y Calidad | F36: =VLOOKUP(A36,BBDD!$1:$1048653,11,0) -> Indefinido | G36: =VLOOKUP(A36,BBDD!$1:$1048653,13,0) -> Coronel Rol Tierra | H36: =VLOOKUP(A36,BBDD!$1:$1048653,14,0) -> Gerencia Corp. Negocio Seafood | I36: =VLOOKUP(A36,BBDD!$1:$1048653,16,0) -> Rol General (Cargo permanente o proyección indefinido) | J36: =VLOOKUP(A36,BBDD!$1:$1048653,17,0) | K36: =VLOOKUP(A36,BBDD!$1:$1048653,12,0) -> 42618 | L36: =VLOOKUP(A36,BBDD!$1:$1048653,3,0) -> Orizon S.A | M36: =VLOOKUP(A36,BBDD!$1:$1048653,4,0) -> F1 | N36: =VLOOKUP(A36,BBDD!$1:$1048653,5,0) -> foxtrot.angers@gmail.com | O36: 45954 | P36: Oficina | Q36: Vestimenta y EPP | R36: cambio de talla | T36: Cerrado
A37: 1 | B37: =VLOOKUP(A37,BBDD!$1:$1048653,2,0) -> Usuario Externo | C37: =VLOOKUP(A37,BBDD!$1:$1048653,7,0) -> Usuario Externo | D37: =VLOOKUP(A37,BBDD!$1:$1048653,8,0) -> Usuario Externo | E37: =VLOOKUP(A37,BBDD!$1:$1048653,10,0) -> Usuario Externo | F37: =VLOOKUP(A37,BBDD!$1:$1048653,11,0) -> Usuario Externo | G37: =VLOOKUP(A37,BBDD!$1:$1048653,13,0) -> Usuario Externo | H37: =VLOOKUP(A37,BBDD!$1:$1048653,14,0) -> Usuario Externo | I37: =VLOOKUP(A37,BBDD!$1:$1048653,16,0) -> Usuario Externo | J37: =VLOOKUP(A37,BBDD!$1:$1048653,17,0) | K37: =VLOOKUP(A37,BBDD!$1:$1048653,12,0) -> Usuario Externo | L37: =VLOOKUP(A37,BBDD!$1:$1048653,3,0) -> Usuario Externo | M37: =VLOOKUP(A37,BBDD!$1:$1048653,4,0) -> Usuario Externo | N37: =VLOOKUP(A37,BBDD!$1:$1048653,5,0) -> Usuario Externo | O37: 45954 | P37: Oficina | Q37: Reclutamiento y Selección | R37: Consulta por personal de reclutamiento | S37: Se indica correo de reclutamiento | T37: Cerrado
A38: 1 | B38: =VLOOKUP(A38,BBDD!$1:$1048653,2,0) -> Usuario Externo | C38: =VLOOKUP(A38,BBDD!$1:$1048653,7,0) -> Usuario Externo | D38: =VLOOKUP(A38,BBDD!$1:$1048653,8,0) -> Usuario Externo | E38: =VLOOKUP(A38,BBDD!$1:$1048653,10,0) -> Usuario Externo | F38: =VLOOKUP(A38,BBDD!$1:$1048653,11,0) -> Usuario Externo | G38: =VLOOKUP(A38,BBDD!$1:$1048653,13,0) -> Usuario Externo | H38: =VLOOKUP(A38,BBDD!$1:$1048653,14,0) -> Usuario Externo | I38: =VLOOKUP(A38,BBDD!$1:$1048653,16,0) -> Usuario Externo | J38: =VLOOKUP(A38,BBDD!$1:$1048653,17,0) | K38: =VLOOKUP(A38,BBDD!$1:$1048653,12,0) -> Usuario Externo | L38: =VLOOKUP(A38,BBDD!$1:$1048653,3,0) -> Usuario Externo | M38: =VLOOKUP(A38,BBDD!$1:$1048653,4,0) -> Usuario Externo | N38: =VLOOKUP(A38,BBDD!$1:$1048653,5,0) -> Usuario Externo | O38: 45954 | P38: Oficina | Q38: Reclutamiento y Selección | R38: consulta por practica laboral | S38: Derivado a Karina Cruces | T38: Cerrado
A39: 16039446 | B39: =VLOOKUP(A39,BBDD!$1:$1048653,2,0) -> 16.039.446-3 | C39: =VLOOKUP(A39,BBDD!$1:$1048653,7,0) -> Bastias Quezada Francisco Andres | D39: =VLOOKUP(A39,BBDD!$1:$1048653,8,0) -> Motorista | E39: =VLOOKUP(A39,BBDD!$1:$1048653,10,0) -> Gerencia de Flota y Abastecimiento de Materias Primas | F39: =VLOOKUP(A39,BBDD!$1:$1048653,11,0) -> Indefinido | G39: =VLOOKUP(A39,BBDD!$1:$1048653,13,0) -> Coronel Rol Flota | H39: =VLOOKUP(A39,BBDD!$1:$1048653,14,0) -> Gerencia Corp. Negocio Seafood | I39: =VLOOKUP(A39,BBDD!$1:$1048653,16,0) -> Rol General (Cargo permanente o proyección indefinido) | J39: =VLOOKUP(A39,BBDD!$1:$1048653,17,0) | K39: =VLOOKUP(A39,BBDD!$1:$1048653,12,0) -> 41047 | L39: =VLOOKUP(A39,BBDD!$1:$1048653,3,0) -> Orizon S.A | M39: =VLOOKUP(A39,BBDD!$1:$1048653,4,0) -> F1 | N39: =VLOOKUP(A39,BBDD!$1:$1048653,5,0) -> francisco.bastias19@gmail.com | O39: 45954 | P39: Teléfono | Q39: Beneficios | R39: Acceso portal Mirax, elección de regalo | S39: Enviar correo a personas.biobio@nutrisco.com | T39: Cerrado
A40: 1 | B40: 16328477-4 | C40: =VLOOKUP(A40,BBDD!$1:$1048653,7,0) -> Usuario Externo | D40: =VLOOKUP(A40,BBDD!$1:$1048653,8,0) -> Usuario Externo | E40: =VLOOKUP(A40,BBDD!$1:$1048653,10,0) -> Usuario Externo | F40: =VLOOKUP(A40,BBDD!$1:$1048653,11,0) -> Usuario Externo | G40: =VLOOKUP(A40,BBDD!$1:$1048653,13,0) -> Usuario Externo | H40: =VLOOKUP(A40,BBDD!$1:$1048653,14,0) -> Usuario Externo | I40: =VLOOKUP(A40,BBDD!$1:$1048653,16,0) -> Usuario Externo | J40: =VLOOKUP(A40,BBDD!$1:$1048653,17,0) | K40: =VLOOKUP(A40,BBDD!$1:$1048653,12,0) -> Usuario Externo | L40: =VLOOKUP(A40,BBDD!$1:$1048653,3,0) -> Usuario Externo | M40: =VLOOKUP(A40,BBDD!$1:$1048653,4,0) -> Usuario Externo | N40: =VLOOKUP(A40,BBDD!$1:$1048653,5,0) -> Usuario Externo | O40: 45954 | P40: Oficina | Q40: Asistencia | R40: Horas extras y cambio de empresa | S40: enviada la informacion de las horas y cambio de empresa EST | T40: Cerrado
...

Sheet Lista desplegable
D1: Oficina | F1: Remuneraciones | I1: Abierto
D2: Teléfono | F2: Asistencia | I2: Cerrado
D3: E-mail | F3: Contrato
D4: Otro | F4: Documentos
F5: Finiquito
F6: Vacaciones
F7: Fotografía
F8: Beneficios
F9: Licencia Médica
F10: Asignación Familiar
F11: Seguro de Salud
F12: EST
F13: Vestimenta y EPP
F14: Credencial
F15: Buk
F16: Reclutamiento y Selección
F17: Otro
